#VRML_SIM R2019a utf8
WorldInfo {
}
Viewpoint {
  orientation 0.07019450652973251 -0.9694382372564139 -0.2350792109018238 3.705136336438169
  position 0.8955005019876183 3.016502941410737 -3.1477055236076907
}
TexturedBackground {
}
TexturedBackgroundLight {
}
Floor {
}
Solid {
  children [
    Group {
      children [
        Transform {
          translation 0 0.49 0
          rotation 0.7071067811865475 0 0.7071067811865475 0.349066
          children [
            Shape {
              appearance DEF Color_Blue PBRAppearance {
                baseColor 0.12549019607843137 0.2901960784313726 0.5294117647058824
                roughness 1
                metalness 0
              }
              geometry DEF Stick_ Box {
                size 0.08 1 0.08
              }
            }
          ]
        }
        Transform {
          translation 0 0.49 0.8
          rotation 0.7071067811865475 0 -0.7071067811865475 -0.349066
          children [
            Shape {
              appearance USE Color_Blue
              geometry USE Stick_
            }
          ]
        }
        Transform {
          translation -0.8 0.49 0
          rotation 0.7071067811865475 0 -0.7071067811865475 0.349066
          children [
            Shape {
              appearance USE Color_Blue
              geometry USE Stick_
            }
          ]
        }
        Transform {
          translation -0.8 0.49 0.8
          rotation -0.7071067811865475 0 -0.7071067811865475 0.349066
          children [
            Shape {
              appearance USE Color_Blue
              geometry USE Stick_
            }
          ]
        }
        Transform {
          translation -0.4 1 0.4
          children [
            Shape {
              appearance USE Color_Blue
              geometry Box {
                size 0.8 0.05 0.8
              }
            }
          ]
        }
        Transform {
          translation 0 0.49 0.4
          rotation 1 0 0 1.5708
          children [
            Shape {
              appearance USE Color_Blue
              geometry DEF Support_ Cylinder {
                height 0.8
                radius 0.03
              }
            }
          ]
        }
        Transform {
          translation -0.8 0.49 0.4
          rotation 1 0 0 1.5708
          children [
            Shape {
              appearance USE Color_Blue
              geometry USE Support_
            }
          ]
        }
        Transform {
          translation -0.4 0.49 0
          rotation 0 0 1 1.5708
          children [
            Shape {
              appearance USE Color_Blue
              geometry USE Support_
            }
          ]
        }
        Transform {
          translation -0.4 0.49 0.8
          rotation 0 0 1 1.5708
          children [
            Shape {
              appearance USE Color_Blue
              geometry USE Support_
            }
          ]
        }
      ]
    }
    Group {
      children [
        Transform {
          translation -0.4 1.3 0.4
          children [
            Shape {
              appearance DEF Color_Red_ PBRAppearance {
                baseColor 0.6431372549019608 0 0
                roughness 1
                metalness 0
              }
              geometry Cylinder {
                height 0.6
                radius 0.05
              }
            }
          ]
        }
        Transform {
          translation -0.4 1.5 0.4
          children [
            Shape {
              appearance USE Color_Red_
              geometry Box {
                size 0.1 0.1 0.2
              }
            }
          ]
        }
        HingeJoint {
          jointParameters HingeJointParameters {
            axis 0 1 0
            anchor -0.4 1.5 0.5
            minStop -0.785398
            maxStop 0.785398
          }
          endPoint Solid {
            translation -0.4 1.5 0.6
            rotation 1 0 0 1.5708
            children [
              Group {
                children [
                  Shape {
                    appearance USE Color_Red_
                    geometry Cylinder {
                      height 0.3
                      radius 0.02
                    }
                  }
                  Transform {
                    translation 0 0.15 0
                    children [
                      Shape {
                        appearance USE Color_Red_
                        geometry Box {
                          size 0.05 0.2 0.1
                        }
                      }
                    ]
                  }
                ]
              }
            ]
            physics Physics {
            }
          }
        }
      ]
    }
    Group {
      children [
        Transform {
          translation -0.4 1.5 0.2
          children [
            HingeJoint {
              jointParameters HingeJointParameters {
                axis 0 0 1
                anchor 0 0 0.08
              }
              endPoint Solid {
                translation 0 0 0.08
                rotation 0 0 1 0
                children [
                  DEF Helices Group {
                    children [
                      Transform {
                        translation 0 0.1 0
                        children [
                          Shape {
                            appearance USE Color_Red_
                            geometry DEF Helice Box {
                              size 0.04 0.2 0.04
                            }
                          }
                        ]
                      }
                      Transform {
                        translation 0 -0.1 0
                        children [
                          Shape {
                            appearance USE Color_Red_
                            geometry USE Helice
                          }
                        ]
                      }
                      Transform {
                        translation 0.1 0 0
                        rotation 0 0 1 1.5708
                        children [
                          Shape {
                            appearance USE Color_Red_
                            geometry USE Helice
                          }
                        ]
                      }
                      Transform {
                        translation -0.1 0 0
                        rotation 0 0 1 1.5708
                        children [
                          Shape {
                            appearance USE Color_Red_
                            geometry USE Helice
                          }
                        ]
                      }
                      Transform {
                        translation 0 0.2 0
                        children [
                          Shape {
                            appearance USE Color_Red_
                            geometry DEF Final_ Box {
                              size 0.05 0.1 0.1
                            }
                          }
                        ]
                      }
                      Transform {
                        translation 0 -0.2 0
                        children [
                          Shape {
                            appearance USE Color_Red_
                            geometry USE Final_
                          }
                        ]
                      }
                      Transform {
                        translation 0.2 0 0
                        rotation 0 0 1 1.5708
                        children [
                          Shape {
                            appearance USE Color_Red_
                            geometry USE Final_
                          }
                        ]
                      }
                      Transform {
                        translation -0.2 0 0
                        rotation 0 0 1 1.5708
                        children [
                          Shape {
                            appearance USE Color_Red_
                            geometry USE Final_
                          }
                        ]
                      }
                    ]
                  }
                  Transform {
                    rotation 0 0 1 0.785398
                    children [
                      USE Helices
                    ]
                  }
                ]
                name "solid(1)"
                physics Physics {
                }
              }
            }
          ]
        }
      ]
    }
  ]
}
