#VRML_SIM R2019a utf8
WorldInfo {
}
Viewpoint {
  orientation 0.27587454286655666 -0.9363404670592848 -0.2171629948802716 4.885046577921247
  position 1.0128545391141253 2.132745024076842 0.7503202895080406
}
TexturedBackground {
}
TexturedBackgroundLight {
}
Floor {
}
Solid {
  children [
    Group {
      children [
        Transform {
          translation 0 0.49 0
          rotation 0.7071067811865475 0 0.7071067811865475 0.349066
          children [
            Shape {
              appearance DEF Color_Blue PBRAppearance {
                baseColor 0.12549019607843137 0.2901960784313726 0.5294117647058824
                roughness 1
                metalness 0
              }
              geometry DEF Stick_ Box {
                size 0.08 1 0.08
              }
            }
          ]
        }
        Transform {
          translation 0 0.49 0.8
          rotation 0.7071067811865475 0 -0.7071067811865475 -0.349066
          children [
            Shape {
              appearance USE Color_Blue
              geometry USE Stick_
            }
          ]
        }
        Transform {
          translation -0.8 0.49 0
          rotation 0.7071067811865475 0 -0.7071067811865475 0.349066
          children [
            Shape {
              appearance USE Color_Blue
              geometry USE Stick_
            }
          ]
        }
        Transform {
          translation -0.8 0.49 0.8
          rotation -0.7071067811865475 0 -0.7071067811865475 0.349066
          children [
            Shape {
              appearance USE Color_Blue
              geometry USE Stick_
            }
          ]
        }
        Transform {
          translation -0.4 1 0.4
          children [
            Shape {
              appearance USE Color_Blue
              geometry Box {
                size 0.8 0.05 0.8
              }
            }
          ]
        }
        Transform {
          translation 0 0.49 0.4
          rotation 1 0 0 1.5708
          children [
            Shape {
              appearance USE Color_Blue
              geometry DEF Support_ Cylinder {
                height 0.8
                radius 0.03
              }
            }
          ]
        }
        Transform {
          translation -0.8 0.49 0.4
          rotation 1 0 0 1.5708
          children [
            Shape {
              appearance USE Color_Blue
              geometry USE Support_
            }
          ]
        }
        Transform {
          translation -0.4 0.49 0
          rotation 0 0 1 1.5708
          children [
            Shape {
              appearance USE Color_Blue
              geometry USE Support_
            }
          ]
        }
        Transform {
          translation -0.4 0.49 0.8
          rotation 0 0 1 1.5708
          children [
            Shape {
              appearance USE Color_Blue
              geometry USE Support_
            }
          ]
        }
      ]
    }
    Group {
      children [
        Transform {
          translation -0.4 1.3 0.4
          children [
            Shape {
              appearance DEF Color_Red_ PBRAppearance {
                baseColor 0.6431372549019608 0 0
                roughness 1
                metalness 0
              }
              geometry Cylinder {
                height 0.6
                radius 0.05
              }
            }
          ]
        }
        HingeJoint {
          jointParameters HingeJointParameters {
            axis 0 1 0
            anchor -0.4 1.5 0.45
            minStop -0.785398
            maxStop 0.785398
          }
          endPoint Solid {
            translation -0.4 1.5 0.6
            rotation 1 0 0 1.5708
            children [
              Group {
                children [
                  Shape {
                    appearance USE Color_Red_
                    geometry Cylinder {
                      height 0.3
                      radius 0.02
                    }
                  }
                  Transform {
                    translation 0 0.15 0
                    children [
                      Shape {
                        appearance USE Color_Red_
                        geometry Box {
                          size 0.05 0.2 0.1
                        }
                      }
                    ]
                  }
                ]
              }
            ]
            physics Physics {
            }
          }
        }
      ]
    }
  ]
}
